Workbook

Sheet Comps Table
A1: ASX COPPER & BASE METALS — COMPARABLE COMPANIES ANALYSIS
A2: Share prices & metal spot prices sourced live via IRESS RTD | Financial data from ASX company announcements (Appendix 5B / Quarterly Activities Reports) — March 2026 quarter | All figures in A$M unless stated | Guidance midpoints used throughout
A4: # | B4: Company Name | C4: ASX Code | D4: Share Price (A$/share) | E4: Shares on Issue (M) | F4: Market Cap (A$M) | G4: Net (Cash) / Debt (A$M) | H4: EV (A$M) | I4: CuEq Guidance (kt pa) ⁽¹⁾ | J4: EV / CuEq (A$/t) | K4: ⚑
A5: 1 | B5: Aeris Resources Limited | C5: AIS | D5: =@IRESSRtd("Quote","13","0","AIS") | E5: 1197.1688 | F5: =D5*E5 | G5: -149.8 | H5: =F5+G5 | I5: =Assumptions!N16 | J5: =IF(I5>0,H5*1000/I5,"n/a") | K5: †
A6: 2 | B6: AIC Mines Limited | C6: A1M | D6: =@IRESSRtd("Quote","13","0","A1M") | E6: 798 | F6: =D6*E6 | G6: 14.2 | H6: =F6+G6 | I6: =Assumptions!N17 | J6: =IF(I6>0,H6*1000/I6,"n/a") | K6: ‡
A7: 3 | B7: Develop Global Limited | C7: DVP | D7: =@IRESSRtd("Quote","13","0","DVP") | E7: 330 | F7: =D7*E7 | G7: -22 | H7: =F7+G7 | I7: =Assumptions!N18 | J7: =IF(I7>0,H7*1000/I7,"n/a") | K7: ‡
A8: 4 | B8: 29Metals Limited | C8: 29M | D8: =@IRESSRtd("Quote","13","0","29M") | E8: 1747.3 | F8: =D8*E8 | G8: -48 | H8: =F8+G8 | I8: =Assumptions!N19 | J8: =IF(I8>0,H8*1000/I8,"n/a") | K8: ‡
A9: 5 | B9: Aurelia Metals Limited | C9: AMI | D9: =@IRESSRtd("Quote","13","0","AMI") | E9: 1693 | F9: =D9*E9 | G9: -86.1 | H9: =F9+G9 | I9: =Assumptions!N20 | J9: =IF(I9>0,H9*1000/I9,"n/a") | K9: ‡
A10: 6 | B10: Hillgrove Resources Limited | C10: HGO | D10: =@IRESSRtd("Quote","13","0","HGO") | E10: 3410 | F10: =D10*E10 | G10: -25.2 | H10: =F10+G10 | I10: =Assumptions!N21 | J10: =IF(I10>0,H10*1000/I10,"n/a")
A11: 7 | B11: Cyprium Metals Limited | C11: CYM | D11: =@IRESSRtd("Quote","13","0","CYM") | E11: 492.2 | F11: =D11*E11 | G11: -54.5 | H11: =F11+G11 | I11: =Assumptions!N22 | J11: =IF(I11>0,H11*1000/I11,"n/a") | K11: §
A12: 8 | B12: Capstone Copper Corp. | C12: CSC | D12: =@IRESSRtd("Quote","13","0","CSC") | E12: 763.7 | F12: =D12*E12 | G12: 1143 | H12: =F12+G12 | I12: =Assumptions!N23 | J12: =IF(I12>0,H12*1000/I12,"n/a") | K12: ‡
A13: 9 | B13: Sandfire Resources Limited | C13: SFR | D13: =@IRESSRtd("Quote","13","0","SFR") | E13: 466.6 | F13: =D13*E13 | G13: -76 | H13: =F13+G13 | I13: =Assumptions!N24 | J13: =IF(I13>0,H13*1000/I13,"n/a") | K13: †
A16: FOOTNOTES & DISCLOSURE NOTES
A17: ⁽¹⁾ CuEq Guidance | B17: Guidance midpoints used. Polymetallic CuEq calculated using live IRESS spot prices (see Assumptions sheet, Section 2). Guidance ranges and data sources are detailed in the Assumptions sheet.
A18: † Company-disclosed CuEq | B18: AIS (40–49 kt, FY2026) and SFR (149–165 kt, FY2026): CuEq as disclosed by the company in quarterly activities reports. Each company's own price assumptions are embedded in those figures.
A19: ‡ Calculated CuEq | B19: A1M, DVP, 29M, AMI, CSC: CuEq calculated from individual metal production guidance midpoints using live IRESS spot prices (Copper COPNY.ID, Gold SPTGLD.IF, Silver SPTSLV.IF, Zinc ZINC.LME, Lead LEAD.LME). Figures will change in real-time as spot prices move.
A20: § Pre-production run-rate (CYM) | B20: Cyprium Metals is pre-production. Phase 1 Nifty SX-EW cathode restart is targeting first production in Q3 CY2026 at a run-rate of approximately 7,000 tpa Cu cathode. CuEq figure shown is the annualised Phase 1 run-rate, not FY2026 actual production. EV/CuEq for CYM should be interpreted as a development-stage multiple, not a producing-company multiple.
A21: CSC note | B21: Capstone Copper Corp. is a Canadian company listed on ASX via CHESS Depository Interests (CDIs, 1:1 ratio). All financials are in USD converted to AUD at 0.645 (approximate implied rate at data sourcing). Capstone does not file ASX Appendix 5B; financial data is sourced from Canadian MD&A (Q1 CY2026, 29-Apr-2026). Its scale (200–230 kt Cu guidance) is substantially larger than other peers in this table.
A22: DVP note | B22: Develop Global's Woodlawn annual copper and zinc guidance figures are LOM run-rate estimates. Formal FY2026 annual Cu/Zn guidance in kt has not been published as a specific annual target. Pb and Ag co-product guidance is not quantified and has been excluded from the CuEq calculation.
A23: Net (Cash)/Debt | B23: Shown using accounting convention: positive = net debt position; parenthetical (negative) = net cash position. Figures from most recent Appendix 5B quarterly cashflow report (March 2026 quarter). USD-denominated debt (29M: US$120M RCF; CYM: US$27.3M Nebari; CSC: US$1,131.8M) converted at 0.645 AUDUSD.
A24: Data pull date | B24: Financial data and production guidance sourced from ASX announcements released April–May 2026 (reflecting March 2026 quarter). Share prices are live via IRESS RTD. Metal prices are live via IRESS RTD. This table refreshes automatically when IRESS is connected.
A26: LIVE METAL PRICE MONITOR (via IRESS RTD)
A27: Cu (USD/t) | B27: =@IRESSRtd("Quote","13","0","COPNY.ID") | C27: Au (USD/oz) | D27: =@IRESSRtd("Quote","13","0","SPTGLD.IF") | E27: Ag (USD/oz) | F27: =@IRESSRtd("Quote","13","0","SPTSLV.IF") | G27: Zn (USD/t) | H27: =@IRESSRtd("Quote","13","0","ZINC.LME") | I27: Pb (USD/t) | J27: AUD/USD | K27: =@IRESSRtd("Quote","13","0","AUDUSD.FX")

Sheet Assumptions
A1: ASSUMPTIONS, CuEq CALCULATIONS & DATA SOURCES
A2: ASX Copper & Base Metals Comps | Data sourced from ASX company announcements (asx.com.au)
A3: SECTION 1 — METAL PRICE ASSUMPTIONS (live via IRESS RTD)
A4: Metal | B4: IRESS Symbol | C4: Live Price | D4: Unit | E4: Notes / Description
A5: Copper | B5: COPNY.ID | C5: =@IRESSRtd("Quote","13","0","COPNY.ID") | D5: USD/t | E5: LME Copper (Grade A)
A6: Gold | B6: SPTGLD.IF | C6: =@IRESSRtd("Quote","13","0","SPTGLD.IF") | D6: USD/oz | E6: Spot Gold (LBMA PM fix)
A7: Silver | B7: SPTSLV.IF | C7: =@IRESSRtd("Quote","13","0","SPTSLV.IF") | D7: USD/oz | E7: Spot Silver
A8: Zinc | B8: ZINC.LME | C8: =@IRESSRtd("Quote","13","0","ZINC.LME") | D8: USD/t | E8: LME Cash Zinc
A9: Lead | B9: LEAD.LME | C9: =@IRESSRtd("Quote","13","0","LEAD.LME") | D9: USD/t | E9: LME Cash Lead
A10: AUD/USD | B10: AUDUSD.FX | C10: =@IRESSRtd("Quote","13","0","AUDUSD.FX") | D10: AUD/USD | E10: Spot FX – used for USD→AUD conversion
A13: SECTION 2 — CuEq PRODUCTION CALCULATIONS
A14: CuEq methodology: CuEq (kt) = Cu_kt + Σ [ By-product_guidance × by-product_price / copper_price ] | Gold & Silver in koz (×1,000 oz/koz); Cu, Zn, Pb prices in USD/t; Au, Ag prices in USD/oz | Units resolve to kt: (koz × USD/oz) / (USD/t) = kt | † Company-disclosed CuEq used (col M). ‡ Calculated from components (col L). § Pre-production annualised run-rate.
A15: Ticker | B15: Cu Guide (kt mid) | C15: Au Guide (koz mid) | D15: Ag Guide (koz mid) | E15: Zn Guide (kt mid) | F15: Pb Guide (kt mid) | G15: Cu→CuEq (kt) | H15: Au→CuEq (kt) | I15: Ag→CuEq (kt) | J15: Zn→CuEq (kt) | K15: Pb→CuEq (kt) | L15: CALC CuEq (kt) | M15: DISC CuEq (kt) | N15: CuEq USED (kt) | O15: Flag | P15: Guidance Source
A16: AIS | B16: 26.5 | C16: 41 | D16: 0 | E16: 0 | F16: 0 | G16: =B16 | H16: =C16*$C$6/$C$5 | I16: =D16*$C$7/$C$5 | J16: =E16*$C$8/$C$5 | K16: =F16*$C$9/$C$5 | L16: =SUM(G16:K16) | M16: 44.5 | N16: =IF(M16>0,M16,L16) | O16: † | P16: FY2026 production guidance (40–49 kt CuEq); Q3 FY26 Quarterly Activities Report, Apr-2026
A17: A1M | B17: 13 | C17: 6.25 | D17: 0 | E17: 0 | F17: 0 | G17: =B17 | H17: =C17*$C$6/$C$5 | I17: =D17*$C$7/$C$5 | J17: =E17*$C$8/$C$5 | K17: =F17*$C$9/$C$5 | L17: =SUM(G17:K17) | N17: =IF(M17>0,M17,L17) | O17: ‡ | P17: FY2026 guidance (12,800–13,200 t Cu + 6,000–6,500 oz Au); Q3 FY26 Quarterly, Apr-2026
A18: DVP | B18: 10 | C18: 0 | D18: 0 | E18: 30 | F18: 0 | G18: =B18 | H18: =C18*$C$6/$C$5 | I18: =D18*$C$7/$C$5 | J18: =E18*$C$8/$C$5 | K18: =F18*$C$9/$C$5 | L18: =SUM(G18:K18) | N18: =IF(M18>0,M18,L18) | O18: ‡ | P18: Woodlawn LOM run-rate (~10 ktpa Cu, ~30 ktpa Zn); FY2026 specific annual guidance not formally published; Q3 FY26 Quarterly, Apr-2026
A19: 29M | B19: 22 | C19: 10 | D19: 500 | E19: 15 | F19: 0 | G19: =B19 | H19: =C19*$C$6/$C$5 | I19: =D19*$C$7/$C$5 | J19: =E19*$C$8/$C$5 | K19: =F19*$C$9/$C$5 | L19: =SUM(G19:K19) | N19: =IF(M19>0,M19,L19) | O19: ‡ | P19: Revised FY2026 guidance; Q1 CY26 Quarterly, Apr-2026 (Cu 20–24 kt; Zn 5–25 kt; Au 6–14 koz; Ag 400–600 koz)
A20: AMI | B20: 2.75 | C20: 47.5 | D20: 0 | E20: 28 | F20: 18 | G20: =B20 | H20: =C20*$C$6/$C$5 | I20: =D20*$C$7/$C$5 | J20: =E20*$C$8/$C$5 | K20: =F20*$C$9/$C$5 | L20: =SUM(G20:K20) | N20: =IF(M20>0,M20,L20) | O20: ‡ | P20: Upgraded FY2026 guidance; Q3 FY26 Quarterly, Apr-2026 (Cu 2.5–3.0 kt; Au 45–50 koz; Zn 24–32 kt; Pb 14–22 kt)
A21: HGO | B21: 13.375 | C21: 0 | D21: 0 | E21: 0 | F21: 0 | G21: =B21 | H21: =C21*$C$6/$C$5 | I21: =D21*$C$7/$C$5 | J21: =E21*$C$8/$C$5 | K21: =F21*$C$9/$C$5 | L21: =SUM(G21:K21) | N21: =IF(M21>0,M21,L21) | P21: CY2026 guidance (12,750–14,000 t Cu); Q4 CY25 Quarterly Activities Report, Jan-2026
A22: CYM | B22: 0 | C22: 0 | D22: 0 | E22: 0 | F22: 0 | G22: =B22 | H22: =C22*$C$6/$C$5 | I22: =D22*$C$7/$C$5 | J22: =E22*$C$8/$C$5 | K22: =F22*$C$9/$C$5 | L22: =SUM(G22:K22) | M22: 7 | N22: =IF(M22>0,M22,L22) | O22: § | P22: Phase 1 Nifty Copper Complex restart targeting Q3 CY26; run-rate ~7 ktpa Cu cathode; Q1 CY26 Quarterly, Apr-2026
A23: CSC | B23: 215 | C23: 0 | D23: 0 | E23: 0 | F23: 0 | G23: =B23 | H23: =C23*$C$6/$C$5 | I23: =D23*$C$7/$C$5 | J23: =E23*$C$8/$C$5 | K23: =F23*$C$9/$C$5 | L23: =SUM(G23:K23) | N23: =IF(M23>0,M23,L23) | O23: ‡ | P23: CY2026 production guidance (200–230 kt Cu); Q1 CY26 Results, 29-Apr-2026 (Pinto Valley AZ + Cozamin MX + Mantos Blancos CL + Mantoverde CL)
A24: SFR | B24: 0 | C24: 0 | D24: 0 | E24: 0 | F24: 0 | G24: =B24 | H24: =C24*$C$6/$C$5 | I24: =D24*$C$7/$C$5 | J24: =E24*$C$8/$C$5 | K24: =F24*$C$9/$C$5 | L24: =SUM(G24:K24) | M24: 157 | N24: =IF(M24>0,M24,L24) | O24: † | P24: FY2026 guidance (149–165 kt CuEq; guiding to lower half); Q3 FY26 Quarterly, 23-Apr-2026 (MATSA Spain + Motheo Botswana)
A28: SECTION 3 — DATA SOURCES
A29: All data sourced from ASX company announcements (asx.com.au) and company investor relations pages. All figures in A$M unless noted. USD-denominated items converted at 0.645 AUDUSD (implied rate at sourcing).
A30: 3A. SHARES ON ISSUE
A31: AIS | B31: Aeris Resources Limited | C31: 1197.1688 | D31: Confirmed: 1,197,168,782 shares on issue
A32: A1M | B32: AIC Mines Limited | C32: 798 | D32: Q3 FY26 Quarterly Report (797.6M at 28-Mar-26), Apr-2026
A33: DVP | B33: Develop Global Limited | C33: 330 | D33: Q3 FY26 Quarterly / market data, Apr-2026 (~329.99M shares)
A34: 29M | B34: 29Metals Limited | C34: 1747.3 | D34: Post-entitlement offer (374.95M new shares Feb-2026); Q1 CY26 Quarterly, Apr-2026
A35: AMI | B35: Aurelia Metals Limited | C35: 1693 | D35: Q3 FY26 Quarterly / market data, Apr-2026
A36: HGO | B36: Hillgrove Resources Limited | C36: 3410 | D36: Q1 CY26 Quarterly / market data, Apr-2026
A37: CYM | B37: Cyprium Metals Limited | C37: 492.2 | D37: Q1 CY26 Quarterly; post A$80M placement + A$41M further raise; post 1:10 consolidation Oct-2025; Apr-2026
A38: CSC | B38: Capstone Copper Corp. | C38: 763.7 | D38: Q1 CY26 MD&A (Canadian disclosure), 29-Apr-2026
A39: SFR | B39: Sandfire Resources Limited | C39: 466.6 | D39: Q3 FY26 Quarterly (466.58M at 28-Mar-26), 23-Apr-2026
A42: 3B. NET CASH / (DEBT) — MOST RECENT QUARTERLY (APP 5B OR EQUIVALENT)
A43: Ticker | B43: Company | C43: Cash (A$M) | D43: Debt (A$M) | E43: Net (Cash)/Debt (A$M) | F43: Qtr End | G43: Source
A44: AIS | B44: Aeris Resources Limited | C44: 149.8 | D44: 0 | E44: -149.8 | F44: 31-Mar-26 | G44: Debt-free from Dec-2025. Tritton Cu mine (NSW) + Cracow Au mine (Qld).
A45: A1M | B45: AIC Mines Limited | C45: 31.1 | D45: 45.3 | E45: 14.2 | F45: 31-Mar-26 | G45: Eloise Cu mine (NW Qld). Q3 cash depressed – A$8.3M concentrate on-site, shipped Apr. Trafigura facility A$45.3M.
A46: DVP | B46: Develop Global Limited | C46: 180 | D46: 158 | E46: -22 | F46: 31-Mar-26 | G46: Woodlawn (NSW): Cu/Zn/Pb/Ag polymetallic. Also has large mining services division (>A$50M/qtr revenue). Pb & Ag guidance not quantified.
A47: 29M | B47: 29Metals Limited | C47: 234 | D47: 186 | E47: -48 | F47: 31-Mar-26 | G47: Golden Grove (WA): Cu–Zn–Au–Ag. Zn guidance materially cut (Xantho Extended geotechnical event). Net cash A$48M per co. (31-Mar-26). US$120M RCF converted @ 0.645.
...
